<?xml version="1.0" ?>
<!-- =================================================================================== -->
<!-- |    This document was autogenerated by xacro from ffw_lg2_leader.urdf.xacro      | -->
<!-- |    EDITING THIS FILE BY HAND IS NOT RECOMMENDED                                 | -->
<!-- =================================================================================== -->
<robot name="ffw_lg2_leader">
  <link name="world"/>
  <joint name="joint" type="prismatic">
    <parent link="world"/>
    <child link="arm_base_link"/>
    <origin rpy="0 0 0" xyz="0 0 0"/>
    <axis xyz="0 0 1"/>
    <limit effort="1000" lower="0.0" upper="0.25" velocity="4.8"/>
    <dynamics damping="0.1"/>
  </joint>
  <link name="arm_base_link"/>
  <joint name="arm_l_joint1" type="revolute">
    <parent link="arm_base_link"/>
    <child link="arm_l_link1"/>
    <origin rpy="0 0 0" xyz="0 0 0"/>
    <axis xyz="0 1 0"/>
    <limit effort="1000" lower="-3.14" upper="3.14" velocity="4.8"/>
    <dynamics damping="0.1"/>
  </joint>
  <link name="arm_l_link1"/>
  <joint name="arm_l_joint2" type="revolute">
    <parent link="arm_l_link1"/>
    <child link="arm_l_link2"/>
    <origin rpy="0 0 0" xyz="0 0 0"/>
    <axis xyz="1 0 0"/>
    <limit effort="1000"  lower="0.0" upper="3.14" velocity="4.8"/>
    <dynamics damping="0.1"/>
  </joint>
  <link name="arm_l_link2"/>
  <joint name="arm_l_joint3" type="revolute">
    <parent link="arm_l_link2"/>
    <child link="arm_l_link3"/>
    <origin rpy="0 0 0" xyz="0 0 0"/>
    <axis xyz="0 0 1"/>
    <limit effort="1000" lower="-3.14" upper="3.14" velocity="4.8"/>
    <dynamics damping="0.1"/>
  </joint>
  <link name="arm_l_link3"/>
  <joint name="arm_l_joint4" type="revolute">
    <parent link="arm_l_link3"/>
    <child link="arm_l_link4"/>
    <origin rpy="0 0 0" xyz="0 0 0"/>
    <axis xyz="0 1 0"/>
    <limit effort="1000" lower="-2.9361" upper="1.0786" velocity="4.8"/>
    <dynamics damping="0.1"/>
  </joint>
  <link name="arm_l_link4"/>
  <joint name="arm_l_joint5" type="revolute">
    <parent link="arm_l_link4"/>
    <child link="arm_l_link5"/>
    <origin rpy="0 0 0" xyz="0 0 0"/>
    <axis xyz="0 0 1"/>
    <limit effort="1000" lower="-3.14" upper="3.14" velocity="4.8"/>
    <dynamics damping="0.1"/>
  </joint>
  <link name="arm_l_link5"/>
  <joint name="arm_l_joint6" type="revolute">
    <parent link="arm_l_link5"/>
    <child link="arm_l_link6"/>
    <origin rpy="0 0 0" xyz="0 0 0"/>
    <axis xyz="0 1 0"/>
    <limit effort="1000" lower="-1.57" upper="1.57" velocity="4.8"/>
    <dynamics damping="0.1"/>
  </joint>
  <link name="arm_l_link6"/>
  <joint name="arm_l_joint7" type="revolute">
    <parent link="arm_l_link6"/>
    <child link="arm_l_link7"/>
    <origin rpy="0 0 0" xyz="0 0 0"/>
    <axis xyz="1 0 0"/>
    <limit effort="1000" lower="-1.8201" upper="1.5804" velocity="4.8"/>
    <dynamics damping="0.1"/>
  </joint>
  <link name="arm_l_link7"/>
  <joint name="arm_r_joint1" type="revolute">
    <parent link="arm_base_link"/>
    <child link="arm_r_link1"/>
    <origin rpy="0 0 0" xyz="0 0 0"/>
    <axis xyz="0 1 0"/>
    <limit effort="1000" lower="-3.14" upper="3.14" velocity="4.8"/>
    <dynamics damping="0.1"/>
  </joint>
  <link name="arm_r_link1"/>
  <joint name="arm_r_joint2" type="revolute">
    <parent link="arm_r_link1"/>
    <child link="arm_r_link2"/>
    <origin rpy="0 0 0" xyz="0 0 0"/>
    <axis xyz="1 0 0"/>
    <limit effort="1000" lower="-3.14" upper="0"  velocity="4.8"/>
    <dynamics damping="0.1"/>
  </joint>
  <link name="arm_r_link2"/>
  <joint name="arm_r_joint3" type="revolute">
    <parent link="arm_r_link2"/>
    <child link="arm_r_link3"/>
    <origin rpy="0 0 0" xyz="0 0 0"/>
    <axis xyz="0 0 1"/>
    <limit effort="1000" lower="-3.14" upper="3.14" velocity="4.8"/>
    <dynamics damping="0.1"/>
  </joint>
  <link name="arm_r_link3"/>
  <joint name="arm_r_joint4" type="revolute">
    <parent link="arm_r_link3"/>
    <child link="arm_r_link4"/>
    <origin rpy="0 0 0" xyz="0 0 0"/>
    <axis xyz="0 1 0"/>
    <limit effort="1000" lower="-2.9361" upper="1.0786" velocity="4.8"/>
    <dynamics damping="0.1"/>
  </joint>
  <link name="arm_r_link4"/>
  <joint name="arm_r_joint5" type="revolute">
    <parent link="arm_r_link4"/>
    <child link="arm_r_link5"/>
    <origin rpy="0 0 0" xyz="0 0 0"/>
    <axis xyz="0 0 1"/>
    <limit effort="1000" lower="-3.14" upper="3.14" velocity="4.8"/>
    <dynamics damping="0.1"/>
  </joint>
  <link name="arm_r_link5"/>
  <joint name="arm_r_joint6" type="revolute">
    <parent link="arm_r_link5"/>
    <child link="arm_r_link6"/>
    <origin rpy="0 0 0" xyz="0 0 0"/>
    <axis xyz="0 1 0"/>
    <limit effort="1000" lower="-1.57" upper="1.57" velocity="4.8"/>
    <dynamics damping="0.1"/>
  </joint>
  <link name="arm_r_link6"/>
  <joint name="arm_r_joint7" type="revolute">
    <parent link="arm_r_link6"/>
    <child link="arm_r_link7"/>
    <origin rpy="0 0 0" xyz="0 0 0"/>
    <axis xyz="1 0 0"/>
    <limit effort="1000"  lower="-1.5804" upper="1.8201" velocity="4.8"/>
    <dynamics damping="0.1"/>
  </joint>
  <link name="arm_r_link7"/>
  <joint name="gripper_l_joint1" type="revolute">
    <origin rpy="0 0 0" xyz="0 0 0"/>
    <parent link="arm_l_link7"/>
    <axis xyz="0 1 0"/>
    <child link="gripper_l_link1"/>
    <limit effort="1000"  lower="0.0" upper="1.1" velocity="6.5"/>
  </joint>
  <link name="gripper_l_link1"/>
  <joint name="gripper_r_joint1" type="revolute">
    <origin rpy="0 0 0" xyz="0 0 0"/>
    <parent link="arm_r_link7"/>
    <axis xyz="0 1 0"/>
    <child link="gripper_r_link1"/>
    <limit effort="1000" lower="00" upper="1.1" velocity="6.5"/>
  </joint>
  <link name="gripper_r_link1"/>
  <ros2_control is_async="true" name="ffw_lg2_leader_left" type="system">
    <hardware>
      <plugin>dynamixel_hardware_interface/DynamixelHardware</plugin>
      <param name="port_name">/dev/left_leader</param>
      <param name="baud_rate">4000000</param>
      <param name="dynamixel_model_folder">/param/dxl_model</param>
      <param name="number_of_joints">8</param>
      <param name="number_of_transmissions">8</param>
      <param name="disable_torque_at_init">true</param>
      <param name="transmission_to_joint_matrix">
              1, 0, 0, 0, 0, 0, 0, 0,
              0, 1, 0, 0, 0, 0, 0, 0,
              0, 0, 1, 0, 0, 0, 0, 0,
              0, 0, 0, 1, 0, 0, 0, 0,
              0, 0, 0, 0, 1, 0, 0, 0,
              0, 0, 0, 0, 0, 1, 0, 0,
              0, 0, 0, 0, 0, 0, 1, 0,
              0, 0, 0, 0, 0, 0, 0, 1
            </param>
      <param name="joint_to_transmission_matrix">
              1, 0, 0, 0, 0, 0, 0, 0,
              0, 1, 0, 0, 0, 0, 0, 0,
              0, 0, 1, 0, 0, 0, 0, 0,
              0, 0, 0, 1, 0, 0, 0, 0,
              0, 0, 0, 0, 1, 0, 0, 0,
              0, 0, 0, 0, 0, 1, 0, 0,
              0, 0, 0, 0, 0, 0, 1, 0,
              0, 0, 0, 0, 0, 0, 0, 1
            </param>
      <param name="dynamixel_state_pub_msg_name">dynamixel_hardware_interface/dxl_state</param>
      <param name="get_dynamixel_data_srv_name">dynamixel_hardware_interface/get_dxl_data</param>
      <param name="set_dynamixel_data_srv_name">dynamixel_hardware_interface/set_dxl_data</param>
      <param name="reboot_dxl_srv_name">dynamixel_hardware_interface/reboot_dxl</param>
      <param name="set_dxl_torque_srv_name">dynamixel_hardware_interface/set_dxl_torque</param>
    </hardware>
    <sensor name="sensorxel_l_joy">
      <state_interface name="JOYSTICK X VALUE"/>
      <state_interface name="JOYSTICK Y VALUE"/>
      <state_interface name="JOYSTICK TACT SWITCH"/>
    </sensor>
    <joint name="gripper_l_joint1">
      <command_interface name="effort"/>
      <state_interface name="position"/>
      <state_interface name="velocity"/>
    </joint>
    <joint name="arm_l_joint1">
      <state_interface name="position"/>
    </joint>
    <joint name="arm_l_joint2">
      <state_interface name="position"/>
    </joint>
    <joint name="arm_l_joint3">
      <state_interface name="position"/>
    </joint>
    <joint name="arm_l_joint4">
      <state_interface name="position"/>
    </joint>
    <joint name="arm_l_joint5">
      <state_interface name="position"/>
    </joint>
    <joint name="arm_l_joint6">
      <state_interface name="position"/>
    </joint>
    <joint name="arm_l_joint7">
      <state_interface name="position"/>
    </joint>
    <gpio name="sensorxel_l_joy">
      <param name="type">sensor</param>
      <param name="ID">10</param>
      <state_interface name="JOYSTICK X VALUE"/>
      <state_interface name="JOYSTICK Y VALUE"/>
      <state_interface name="JOYSTICK TACT SWITCH"/>
    </gpio>
    <gpio name="dxl38">
      <param name="type">dxl</param>
      <param name="ID">38</param>
      <command_interface name="Goal Current"/>
      <state_interface name="Present Position"/>
      <state_interface name="Present Velocity"/>
      <param name="Drive Mode">0</param>
      <param name="Operating Mode">0</param>
      <param name="Return Delay Time">0</param>
      <param name="Torque Enable">1</param>
    </gpio>
    <gpio name="dxl31">
      <param name="type">dxl</param>
      <param name="ID">31</param>
      <state_interface name="Present Position"/>
      <param name="Drive Mode">0</param>
      <param name="Operating Mode">3</param>
      <param name="Return Delay Time">0</param>
      <param name="Torque Enable">0</param>
    </gpio>
    <gpio name="dxl32">
      <param name="type">dxl</param>
      <param name="ID">32</param>
      <state_interface name="Present Position"/>
      <param name="Drive Mode">1</param>
      <param name="Operating Mode">3</param>
      <param name="Return Delay Time">0</param>
      <param name="Torque Enable">0</param>
    </gpio>
    <gpio name="dxl33">
      <param name="type">dxl</param>
      <param name="ID">33</param>
      <state_interface name="Present Position"/>
      <param name="Drive Mode">1</param>
      <param name="Operating Mode">3</param>
      <param name="Return Delay Time">0</param>
      <param name="Torque Enable">0</param>
    </gpio>
    <gpio name="dxl34">
      <param name="type">dxl</param>
      <param name="ID">34</param>
      <state_interface name="Present Position"/>
      <param name="Drive Mode">0</param>
      <param name="Operating Mode">3</param>
      <param name="Return Delay Time">0</param>
      <param name="Torque Enable">0</param>
    </gpio>
    <gpio name="dxl35">
      <param name="type">dxl</param>
      <param name="ID">35</param>
      <state_interface name="Present Position"/>
      <param name="Drive Mode">1</param>
      <param name="Operating Mode">3</param>
      <param name="Return Delay Time">0</param>
      <param name="Torque Enable">0</param>
    </gpio>
    <gpio name="dxl36">
      <param name="type">dxl</param>
      <param name="ID">36</param>
      <state_interface name="Present Position"/>
      <param name="Drive Mode">0</param>
      <param name="Operating Mode">3</param>
      <param name="Return Delay Time">0</param>
      <param name="Torque Enable">0</param>
    </gpio>
    <gpio name="dxl37">
      <param name="type">dxl</param>
      <param name="ID">37</param>
      <state_interface name="Present Position"/>
      <param name="Drive Mode">1</param>
      <param name="Operating Mode">3</param>
      <param name="Return Delay Time">0</param>
      <param name="Torque Enable">0</param>
    </gpio>
  </ros2_control>
  <ros2_control is_async="true" name="ffw_lg2_leader_right" type="system">
    <hardware>
      <plugin>dynamixel_hardware_interface/DynamixelHardware</plugin>
      <param name="port_name">/dev/right_leader</param>
      <param name="baud_rate">4000000</param>
      <param name="dynamixel_model_folder">/param/dxl_model</param>
      <param name="number_of_joints">8</param>
      <param name="number_of_transmissions">8</param>
      <param name="disable_torque_at_init">true</param>
      <param name="transmission_to_joint_matrix">
              1, 0, 0, 0, 0, 0, 0, 0,
              0, 1, 0, 0, 0, 0, 0, 0,
              0, 0, 1, 0, 0, 0, 0, 0,
              0, 0, 0, 1, 0, 0, 0, 0,
              0, 0, 0, 0, 1, 0, 0, 0,
              0, 0, 0, 0, 0, 1, 0, 0,
              0, 0, 0, 0, 0, 0, 1, 0,
              0, 0, 0, 0, 0, 0, 0, 1
            </param>
      <param name="joint_to_transmission_matrix">
              1, 0, 0, 0, 0, 0, 0, 0,
              0, 1, 0, 0, 0, 0, 0, 0,
              0, 0, 1, 0, 0, 0, 0, 0,
              0, 0, 0, 1, 0, 0, 0, 0,
              0, 0, 0, 0, 1, 0, 0, 0,
              0, 0, 0, 0, 0, 1, 0, 0,
              0, 0, 0, 0, 0, 0, 1, 0,
              0, 0, 0, 0, 0, 0, 0, 1
            </param>
      <param name="dynamixel_state_pub_msg_name">dynamixel_hardware_interface/dxl_state</param>
      <param name="get_dynamixel_data_srv_name">dynamixel_hardware_interface/get_dxl_data</param>
      <param name="set_dynamixel_data_srv_name">dynamixel_hardware_interface/set_dxl_data</param>
      <param name="reboot_dxl_srv_name">dynamixel_hardware_interface/reboot_dxl</param>
      <param name="set_dxl_torque_srv_name">dynamixel_hardware_interface/set_dxl_torque</param>
    </hardware>
    <sensor name="sensorxel_r_joy">
      <state_interface name="JOYSTICK X VALUE"/>
      <state_interface name="JOYSTICK Y VALUE"/>
      <state_interface name="JOYSTICK TACT SWITCH"/>
    </sensor>
    <joint name="gripper_r_joint1">
      <command_interface name="effort"/>
      <state_interface name="position"/>
      <state_interface name="velocity"/>
    </joint>
    <joint name="arm_r_joint1">
      <state_interface name="position"/>
    </joint>
    <joint name="arm_r_joint2">
      <state_interface name="position"/>
    </joint>
    <joint name="arm_r_joint3">
      <state_interface name="position"/>
    </joint>
    <joint name="arm_r_joint4">
      <state_interface name="position"/>
    </joint>
    <joint name="arm_r_joint5">
      <state_interface name="position"/>
    </joint>
    <joint name="arm_r_joint6">
      <state_interface name="position"/>
    </joint>
    <joint name="arm_r_joint7">
      <state_interface name="position"/>
    </joint>
    <gpio name="sensorxel_r_joy">
      <param name="type">sensor</param>
      <param name="ID">10</param>
      <state_interface name="JOYSTICK X VALUE"/>
      <state_interface name="JOYSTICK Y VALUE"/>
      <state_interface name="JOYSTICK TACT SWITCH"/>
    </gpio>
    <gpio name="dxl8">
      <param name="type">dxl</param>
      <param name="ID">8</param>
      <command_interface name="Goal Current"/>
      <state_interface name="Present Position"/>
      <state_interface name="Present Velocity"/>
      <param name="Drive Mode">1</param>
      <param name="Operating Mode">0</param>
      <param name="Return Delay Time">0</param>
      <param name="Torque Enable">1</param>
    </gpio>
    <gpio name="dxl1">
      <param name="type">dxl</param>
      <param name="ID">1</param>
      <state_interface name="Present Position"/>
      <param name="Drive Mode">1</param>
      <param name="Operating Mode">3</param>
      <param name="Return Delay Time">0</param>
      <param name="Torque Enable">0</param>
    </gpio>
    <gpio name="dxl2">
      <param name="type">dxl</param>
      <param name="ID">2</param>
      <state_interface name="Present Position"/>
      <param name="Drive Mode">1</param>
      <param name="Operating Mode">3</param>
      <param name="Return Delay Time">0</param>
      <param name="Torque Enable">0</param>
    </gpio>
    <gpio name="dxl3">
      <param name="type">dxl</param>
      <param name="ID">3</param>
      <state_interface name="Present Position"/>
      <param name="Drive Mode">1</param>
      <param name="Operating Mode">3</param>
      <param name="Return Delay Time">0</param>
      <param name="Torque Enable">0</param>
    </gpio>
    <gpio name="dxl4">
      <param name="type">dxl</param>
      <param name="ID">4</param>
      <state_interface name="Present Position"/>
      <param name="Drive Mode">1</param>
      <param name="Operating Mode">3</param>
      <param name="Return Delay Time">0</param>
      <param name="Torque Enable">0</param>
    </gpio>
    <gpio name="dxl5">
      <param name="type">dxl</param>
      <param name="ID">5</param>
      <state_interface name="Present Position"/>
      <param name="Drive Mode">1</param>
      <param name="Operating Mode">3</param>
      <param name="Return Delay Time">0</param>
      <param name="Torque Enable">0</param>
    </gpio>
    <gpio name="dxl6">
      <param name="type">dxl</param>
      <param name="ID">6</param>
      <state_interface name="Present Position"/>
      <param name="Drive Mode">1</param>
      <param name="Operating Mode">3</param>
      <param name="Return Delay Time">0</param>
      <param name="Torque Enable">0</param>
    </gpio>
    <gpio name="dxl7">
      <param name="type">dxl</param>
      <param name="ID">7</param>
      <state_interface name="Present Position"/>
      <param name="Drive Mode">1</param>
      <param name="Operating Mode">3</param>
      <param name="Return Delay Time">0</param>
      <param name="Torque Enable">0</param>
    </gpio>
  </ros2_control>
</robot>

